2024-06-20 15:39:02.739 | DEBUG    | Trying to select search APIs in json where text is Based on the issue description, I will use the following search APIs to gather more information about the project:

1. `search_class(class_name: str)`: To search for the `Calculator` class in the codebase.
   Input: `class_name='Calculator'`

2. `search_method_in_file(method_name: str, file_path: str)`: To search for methods related to trigonometry functions (e.g., `sin`, `cos`, etc.) in a specific file where these methods are likely implemented.
   Inputs:
   - `method_name='sin'`
   - `file_path='path_to_file.py'` (assuming the file path is known)

3. `search_method(method_name: str)`: To search for any existing trigonometry functions or related code in the entire codebase.
   Input: `method_name='sin'`

These API calls will help me understand how the calculator's functionality is currently implemented and where I can add new methods to support trigonometric operations.. Try 1 of 5.
2024-06-20 15:39:11.061 | DEBUG    | Extracted a valid json
2024-06-20 15:39:11.073 | DEBUG    | Result of dispatch_intent: ('Found 1 classes with name Calculator in the codebase:\n\n- Search result 1:\n```\n<file>calculator/calculator.py</file>\n<class>Calculator</class>\n<code>\nclass Calculator:\n    def add(self, a, b):\n    def subtract(self, a, b):\n    def multiply(self, a, b):\n    def divide(self, a, b):\n\n</code>\n```\n', 'The tool returned information about class `Calculator`.', True)
2024-06-20 15:39:11.074 | DEBUG    | Result of dispatch_intent: ('Could not find file path_to_file.py in the codebase.', 'Could not find file path_to_file.py in the codebase.', False)
2024-06-20 15:39:11.074 | DEBUG    | Result of dispatch_intent: ('Could not find method sin in the codebase.', 'Could not find method sin in the codebase.', False)
2024-06-20 15:39:59.994 | DEBUG    | Trying to select search APIs in json where text is Based on my analysis, I don't need more context to proceed with solving the issue.

As for the bug locations, since there is no existing implementation of trigonometric functions like `sin`, I can infer that the new method `sin` needs to be added to the `Calculator` class in the file `calculator/calculator.py`.

So, my answers are:

* Do we need more context: No
* Where are bug locations: `<file>calculator/calculator.py</file>` (in the `Calculator` class). Try 1 of 5.
2024-06-20 15:40:03.115 | DEBUG    | Invalid json. Will retry.
2024-06-20 15:40:03.115 | DEBUG    | Trying to select search APIs in json where text is Based on my analysis, I don't need more context to proceed with solving the issue.

As for the bug locations, since there is no existing implementation of trigonometric functions like `sin`, I can infer that the new method `sin` needs to be added to the `Calculator` class in the file `calculator/calculator.py`.

So, my answers are:

* Do we need more context: No
* Where are bug locations: `<file>calculator/calculator.py</file>` (in the `Calculator` class). Try 2 of 5.
2024-06-20 15:40:05.578 | DEBUG    | Invalid json. Will retry.
2024-06-20 15:40:05.578 | DEBUG    | Trying to select search APIs in json where text is Based on my analysis, I don't need more context to proceed with solving the issue.

As for the bug locations, since there is no existing implementation of trigonometric functions like `sin`, I can infer that the new method `sin` needs to be added to the `Calculator` class in the file `calculator/calculator.py`.

So, my answers are:

* Do we need more context: No
* Where are bug locations: `<file>calculator/calculator.py</file>` (in the `Calculator` class). Try 3 of 5.
2024-06-20 15:40:08.285 | DEBUG    | Invalid json. Will retry.
2024-06-20 15:40:08.285 | DEBUG    | Trying to select search APIs in json where text is Based on my analysis, I don't need more context to proceed with solving the issue.

As for the bug locations, since there is no existing implementation of trigonometric functions like `sin`, I can infer that the new method `sin` needs to be added to the `Calculator` class in the file `calculator/calculator.py`.

So, my answers are:

* Do we need more context: No
* Where are bug locations: `<file>calculator/calculator.py</file>` (in the `Calculator` class). Try 4 of 5.
2024-06-20 15:40:11.136 | DEBUG    | Invalid json. Will retry.
2024-06-20 15:40:11.137 | DEBUG    | Trying to select search APIs in json where text is Based on my analysis, I don't need more context to proceed with solving the issue.

As for the bug locations, since there is no existing implementation of trigonometric functions like `sin`, I can infer that the new method `sin` needs to be added to the `Calculator` class in the file `calculator/calculator.py`.

So, my answers are:

* Do we need more context: No
* Where are bug locations: `<file>calculator/calculator.py</file>` (in the `Calculator` class). Try 5 of 5.
2024-06-20 15:40:14.043 | DEBUG    | Failed to extract json after 5 retries with basic prompt. Trying a new prompt
2024-06-20 15:40:18.199 | DEBUG    | Extracted a valid json
2024-06-20 15:40:18.204 | DEBUG    | Result of dispatch_intent: ('Found 1 classes with name Calculator in file calculator/calculator.py:\n\n- Search result 1:\n```\n<file>calculator/calculator.py</file>\n<class>Calculator</class>\n<code>\nclass Calculator:\n    def add(self, a, b):\n        return a + b\n\n    def subtract(self, a, b):\n        return a - b\n\n    def multiply(self, a, b):\n        return a * b\n\n    def divide(self, a, b):\n        return a / b\n\n</code>\n```\n', 'Found 1 classes with name Calculator in file calculator/calculator.py:\n\n', True)
2024-06-20 15:40:18.205 | DEBUG    | Gathered enough information. Invoking write_patch.
2024-06-20 15:40:18.258 | INFO     | Trying to write a patch. Try 1 of 3.
2024-06-20 15:40:57.092 | INFO     | Raw patch produced in try 1. Writing patch into file.
2024-06-20 15:40:57.777 | INFO     | Trying to write a patch. Try 2 of 3.
2024-06-20 15:41:52.027 | INFO     | Raw patch produced in try 2. Writing patch into file.
2024-06-20 15:41:52.416 | ERROR    | Cannot do validation for live issues for now
Traceback (most recent call last):

  File "/opt/auto-code-rover/app/main.py", line 519, in <module>
    main(args)
    │    └ Namespace(command='local-issue', output_dir='output', no_print=False, model='llama3', model_temperature=0.0, conv_round_limit...
    └ <function main at 0x7f1ec4f872e0>

  File "/opt/auto-code-rover/app/main.py", line 119, in main
    run_task_groups(groups, num_processes)
    │               │       └ 1
    │               └ {'local': [<app.raw_tasks.RawLocalTask object at 0x7f1ec7224650>]}
    └ <function run_task_groups at 0x7f1ec2cf11c0>

  File "/opt/auto-code-rover/app/main.py", line 338, in run_task_groups
    run_tasks_serial(all_tasks)
    │                └ [<app.raw_tasks.RawLocalTask object at 0x7f1ec7224650>]
    └ <function run_tasks_serial at 0x7f1ec2cf1260>

  File "/opt/auto-code-rover/app/main.py", line 356, in run_tasks_serial
    run_task_in_subprocess(task)
    │                      └ <app.raw_tasks.RawLocalTask object at 0x7f1ec7224650>
    └ <function run_task_in_subprocess at 0x7f1ec2cf1440>

  File "/opt/auto-code-rover/app/main.py", line 401, in run_task_in_subprocess
    executor.submit(run_raw_task, task)
    │        │      │             └ <app.raw_tasks.RawLocalTask object at 0x7f1ec7224650>
    │        │      └ <function run_raw_task at 0x7f1ec2cf14e0>
    │        └ <function ProcessPoolExecutor.submit at 0x7f1ec7c75ee0>
    └ <concurrent.futures.process.ProcessPoolExecutor object at 0x7f1ec2d11490>

  File "/root/miniconda3/envs/auto-code-rover/lib/python3.11/concurrent/futures/process.py", line 809, in submit
    self._start_executor_manager_thread()
    │    └ <function ProcessPoolExecutor._start_executor_manager_thread at 0x7f1ec7c75c60>
    └ <concurrent.futures.process.ProcessPoolExecutor object at 0x7f1ec2d11490>
  File "/root/miniconda3/envs/auto-code-rover/lib/python3.11/concurrent/futures/process.py", line 748, in _start_executor_manager_thread
    self._launch_processes()
    │    └ <function ProcessPoolExecutor._launch_processes at 0x7f1ec7c75da0>
    └ <concurrent.futures.process.ProcessPoolExecutor object at 0x7f1ec2d11490>
  File "/root/miniconda3/envs/auto-code-rover/lib/python3.11/concurrent/futures/process.py", line 775, in _launch_processes
    self._spawn_process()
    │    └ <function ProcessPoolExecutor._spawn_process at 0x7f1ec7c75e40>
    └ <concurrent.futures.process.ProcessPoolExecutor object at 0x7f1ec2d11490>
  File "/root/miniconda3/envs/auto-code-rover/lib/python3.11/concurrent/futures/process.py", line 785, in _spawn_process
    p.start()
    │ └ <function BaseProcess.start at 0x7f1ec7e7c220>
    └ <ForkProcess name='ForkProcess-1' parent=23 started>
  File "/root/miniconda3/envs/auto-code-rover/lib/python3.11/multiprocessing/process.py", line 121, in start
    self._popen = self._Popen(self)
    │    │        │    │      └ <ForkProcess name='ForkProcess-1' parent=23 started>
    │    │        │    └ <staticmethod(<function ForkProcess._Popen at 0x7f1ec7ee1440>)>
    │    │        └ <ForkProcess name='ForkProcess-1' parent=23 started>
    │    └ None
    └ <ForkProcess name='ForkProcess-1' parent=23 started>
  File "/root/miniconda3/envs/auto-code-rover/lib/python3.11/multiprocessing/context.py", line 281, in _Popen
    return Popen(process_obj)
           │     └ <ForkProcess name='ForkProcess-1' parent=23 started>
           └ <class 'multiprocessing.popen_fork.Popen'>
  File "/root/miniconda3/envs/auto-code-rover/lib/python3.11/multiprocessing/popen_fork.py", line 19, in __init__
    self._launch(process_obj)
    │    │       └ <ForkProcess name='ForkProcess-1' parent=23 started>
    │    └ <function Popen._launch at 0x7f1ec2cf2a20>
    └ <multiprocessing.popen_fork.Popen object at 0x7f1ec3a83210>
  File "/root/miniconda3/envs/auto-code-rover/lib/python3.11/multiprocessing/popen_fork.py", line 71, in _launch
    code = process_obj._bootstrap(parent_sentinel=child_r)
           │           │                          └ 14
           │           └ <function BaseProcess._bootstrap at 0x7f1ec7e7cc20>
           └ <ForkProcess name='ForkProcess-1' parent=23 started>
  File "/root/miniconda3/envs/auto-code-rover/lib/python3.11/multiprocessing/process.py", line 314, in _bootstrap
    self.run()
    │    └ <function BaseProcess.run at 0x7f1ec7e7c180>
    └ <ForkProcess name='ForkProcess-1' parent=23 started>
  File "/root/miniconda3/envs/auto-code-rover/lib/python3.11/multiprocessing/process.py", line 108, in run
    self._target(*self._args, **self._kwargs)
    │    │        │    │        │    └ {}
    │    │        │    │        └ <ForkProcess name='ForkProcess-1' parent=23 started>
    │    │        │    └ (<concurrent.futures.process._SafeQueue object at 0x7f1ec2d09b50>, <multiprocessing.queues.SimpleQueue object at 0x7f1ec2d0b1...
    │    │        └ <ForkProcess name='ForkProcess-1' parent=23 started>
    │    └ <function _process_worker at 0x7f1ec7c751c0>
    └ <ForkProcess name='ForkProcess-1' parent=23 started>
  File "/root/miniconda3/envs/auto-code-rover/lib/python3.11/concurrent/futures/process.py", line 261, in _process_worker
    r = call_item.fn(*call_item.args, **call_item.kwargs)
        │         │   │         │       │         └ {}
        │         │   │         │       └ <concurrent.futures.process._CallItem object at 0x7f1ec2d14e50>
        │         │   │         └ (<app.raw_tasks.RawLocalTask object at 0x7f1ec7e703d0>,)
        │         │   └ <concurrent.futures.process._CallItem object at 0x7f1ec2d14e50>
        │         └ <function run_raw_task at 0x7f1ec2cf14e0>
        └ <concurrent.futures.process._CallItem object at 0x7f1ec2d14e50>

  File "/opt/auto-code-rover/app/main.py", line 429, in run_raw_task
    run_ok = do_inference(task.to_task(), task_output_dir, print_callback)
             │            │    │          │                └ None
             │            │    │          └ '/opt/auto-code-rover/output/1_2024-06-20_15-38-18'
             │            │    └ <function RawLocalTask.to_task at 0x7f1ec2cf0d60>
             │            └ <app.raw_tasks.RawLocalTask object at 0x7f1ec7e703d0>
             └ <function do_inference at 0x7f1ec2cf1580>

  File "/opt/auto-code-rover/app/main.py", line 482, in do_inference
    run_ok = inference.run_one_task(
             │         └ <function run_one_task at 0x7f1ec4dc28e0>
             └ <module 'app.inference' from '/opt/auto-code-rover/app/inference.py'>

  File "/opt/auto-code-rover/app/inference.py", line 443, in run_one_task
    return start_conversation_round_stratified(
           └ <function start_conversation_round_stratified at 0x7f1ec4f87240>

  File "/opt/auto-code-rover/app/inference.py", line 248, in start_conversation_round_stratified
    api_manager.dispatch_intent(
    │           └ <function ProjectApiManager.dispatch_intent at 0x7f1ec4f867a0>
    └ <app.api.manage.ProjectApiManager object at 0x7f1ec3a50990>

> File "/opt/auto-code-rover/app/api/manage.py", line 207, in dispatch_intent
    call_res = func_obj(message_thread, print_callback=print_callback)
               │        │                              └ None
               │        └ <app.data_structures.MessageThread object at 0x7f1ec49d9c50>
               └ <bound method ProjectApiManager.write_patch of <app.api.manage.ProjectApiManager object at 0x7f1ec3a50990>>

  File "/opt/auto-code-rover/app/api/manage.py", line 446, in write_patch
    tool_output = agent_write_patch.run_with_retries(
                  │                 └ <function run_with_retries at 0x7f1ec5453380>
                  └ <module 'app.api.agent_write_patch' from '/opt/auto-code-rover/app/api/agent_write_patch.py'>

  File "/opt/auto-code-rover/app/api/agent_write_patch.py", line 129, in run_with_retries
    patch_is_correct, err_message, log_file = task.validate(diff_file)
                                              │    │        └ '/opt/auto-code-rover/output/1_2024-06-20_15-38-18/extracted_patch_2.diff'
                                              │    └ <function PlainTask.validate at 0x7f1ec5451580>
                                              └ PlainTask(commit_hash='73c83807bb193eedf93d0295f0e5d77df7a1f77d', local_path='/home/calculator_project', problem_statement="I...

  File "/opt/auto-code-rover/app/task.py", line 305, in validate
    raise NotImplementedError("Cannot do validation for live issues for now")

NotImplementedError: Cannot do validation for live issues for now
2024-06-20 15:41:52.422 | DEBUG    | Result of dispatch_intent: ('Cannot do validation for live issues for now', 'The tool returned error message.', False)
2024-06-20 15:41:52.422 | INFO     | Invoked write_patch. Ending workflow.
2024-06-20 15:41:52.920 | INFO     | Task 1 completed successfully.
2024-06-20 15:41:52.921 | INFO     | Please find the generated patch at: /opt/auto-code-rover/output/1_2024-06-20_15-38-18/extracted_patch_2.diff
